#VRML_SIM R2022a utf8
WorldInfo {
}
Viewpoint {
  orientation -0.35322913373366677 -0.001059070120339184 0.9355362405873134 3.1297508193365187
  position 5.262309102571772 -0.11256696010437507 4.569563958344188
}
TexturedBackground {
  texture "empty_office"
}
TexturedBackgroundLight {
}
Floor {
  size 4 4
  tileSize 1 1
}
DEF WALL_1 Solid {
  translation 0 2 0.25
  children [
    DEF WALL_SHAPE Shape {
      appearance PBRAppearance {
        baseColor 0.8 0.8 0.8
        roughness 1
        metalness 0
      }
      geometry Box {
        size 4 0.02 0.5
      }
    }
  ]
  name "wall1"
  boundingObject USE WALL_SHAPE
}
DEF WALL_2 Solid {
  translation 2 1.83656e-06 0.25
  rotation 0 0 1 1.5708
  children [
    USE WALL_SHAPE
  ]
  name "wall2"
  boundingObject USE WALL_SHAPE
}
DEF WALL_3 Solid {
  translation 0 -2 0.25
  children [
    USE WALL_SHAPE
  ]
  name "wall3"
  boundingObject USE WALL_SHAPE
}
DEF WALL_4 Solid {
  translation -2 -1.83656e-06 0.25
  rotation 0 0 1 1.5708
  children [
    USE WALL_SHAPE
  ]
  name "wall4"
  boundingObject USE WALL_SHAPE
}
DEF WALL_5 Solid {
  translation 0 0.5 0.25
  rotation 0 0 1 -3.1415853071795863
  children [
    USE WALL_SHAPE
  ]
  name "wall4(1)"
  boundingObject USE WALL_SHAPE
}
Robot {
  translation 0.0244576 -0.621297 0.41
  children [
    DEF ARM_AXIS1_TRANSL SliderJoint {
      jointParameters JointParameters {
        minStop -0.2
        staticFriction 50
      }
      device [
        LinearMotor {
          name "arm_axis1_transl"
        }
      ]
      endPoint Solid {
        translation 0 0 0.2250000000000001
        children [
          DEF ARM_AXIS1_SHAPE Shape {
            appearance PBRAppearance {
              baseColor 1 0.5 0
              roughness 1
              metalness 0
            }
            geometry Box {
              size 0.05 0.05 0.3
            }
          }
          DEF ARM_AXIS2_ROT HingeJoint {
            jointParameters HingeJointParameters {
              axis 0 0 1
              anchor 0.025 0 0.12
              minStop -1.57
              maxStop 1.57
            }
            device [
              RotationalMotor {
                name "arm_axis2_rot"
              }
            ]
            endPoint Solid {
              translation 0.025 3.46945e-18 0.12
              children [
                DEF ARM_HINGE_SHAPE Shape {
                  appearance PBRAppearance {
                    baseColor 0 1 0
                    roughness 1
                    metalness 0
                  }
                  geometry Sphere {
                    radius 0.038
                  }
                }
                DEF ARM_AXIS3_TRANSL SliderJoint {
                  jointParameters JointParameters {
                    axis 1 0 0
                    minStop -0.1
                    staticFriction 50
                  }
                  device [
                    LinearMotor {
                      name "arm_axis3_transl"
                    }
                  ]
                  endPoint Solid {
                    translation 0.075 0 0
                    children [
                      DEF ARM_AXIS3_SHAPE Shape {
                        appearance PBRAppearance {
                          baseColor 1 0.5 0
                          roughness 1
                          metalness 0
                        }
                        geometry Box {
                          size 0.15 0.05 0.05
                        }
                      }
                      DEF ARM_AXIS4_ROT HingeJoint {
                        jointParameters HingeJointParameters {
                          anchor 0.075 0 0
                          minStop -1.57
                          maxStop 1.57
                        }
                        device [
                          RotationalMotor {
                            name "arm_axis4_rot"
                          }
                        ]
                        endPoint Solid {
                          translation 0.075 0 0
                          rotation 1 0 0 0
                          children [
                            USE ARM_HINGE_SHAPE
                            DEF ARM_LINK1 Solid {
                              translation 0.05 0 0
                              children [
                                DEF ARM_LINK1_SHAPE Shape {
                                  appearance PBRAppearance {
                                    baseColor 1 1 0
                                    roughness 1
                                    metalness 0
                                  }
                                  geometry Box {
                                    size 0.1 0.05 0.05
                                  }
                                }
                                DEF ARM_AXIS5_ROT HingeJoint {
                                  jointParameters HingeJointParameters {
                                    axis 0 1 0
                                    anchor 0.05 0 0
                                    minStop -1.57
                                    maxStop 1.57
                                  }
                                  device [
                                    RotationalMotor {
                                      name "arm_axis5_rot"
                                    }
                                  ]
                                  endPoint Solid {
                                    translation 0.05000000000000003 0 0
                                    rotation 0 1 0 0
                                    children [
                                      USE ARM_HINGE_SHAPE
                                      DEF ARM_LINK2 Solid {
                                        translation 0.05 0 0
                                        children [
                                          DEF ARM_LINK2_SHAPE Shape {
                                            appearance PBRAppearance {
                                              baseColor 1 1 0
                                              roughness 1
                                              metalness 0
                                            }
                                            geometry Box {
                                              size 0.1 0.05 0.05
                                            }
                                          }
                                        ]
                                        boundingObject USE ARM_LINK2_SHAPE
                                        physics Physics {
                                        }
                                      }
                                    ]
                                    boundingObject USE ARM_HINGE_SHAPE
                                    physics Physics {
                                    }
                                  }
                                }
                              ]
                              boundingObject USE ARM_LINK1_SHAPE
                              physics Physics {
                              }
                            }
                          ]
                          boundingObject USE ARM_HINGE_SHAPE
                          physics Physics {
                          }
                        }
                      }
                    ]
                    boundingObject USE ARM_AXIS3_SHAPE
                    physics Physics {
                    }
                  }
                }
              ]
              boundingObject USE ARM_HINGE_SHAPE
              physics Physics {
              }
            }
          }
        ]
        name "solid(2)"
        boundingObject USE ARM_AXIS1_SHAPE
        physics Physics {
        }
      }
    }
    DEF DS_RIGHT DistanceSensor {
      translation 0.305 -0.23 0
      rotation 0 0 1 -0.3
      children [
        DEF DS_SHAPE Shape {
          appearance PBRAppearance {
            baseColor 0 0 1
            roughness 1
            metalness 0
          }
          geometry Box {
            size 0.03 0.03 0.03
          }
        }
      ]
      name "ds_right"
      lookupTable [
        0 0 0
        0.4 1000 0
      ]
    }
    DEF DS_LEFT DistanceSensor {
      translation 0.305 0.23 0
      rotation 0 0 1 0.3
      children [
        USE DS_SHAPE
      ]
      name "ds_left"
      lookupTable [
        0 0 0
        0.4 1000 0
      ]
    }
    DEF LEFT_WHEEL1 HingeJoint {
      jointParameters HingeJointParameters {
        axis 0 1 0
        anchor 0.48 0.33 -0.3
      }
      device [
        RotationalMotor {
          name "left_wheel1"
          maxTorque 100
        }
      ]
      endPoint Solid {
        translation 0.48 0.33 -0.3
        rotation 1 -7.065403087751576e-16 -1.5700895750559056e-16 1.5707999999999966
        children [
          DEF WHEEL_SHAPE Shape {
            appearance PBRAppearance {
              baseColor 0 1 0
              roughness 1
              metalness 0
            }
            geometry Cylinder {
              height 0.1
              radius 0.1
            }
          }
        ]
        boundingObject USE WHEEL_SHAPE
        physics DEF WHEEL_PH Physics {
        }
      }
    }
    DEF RIGHT_WHEEL1 HingeJoint {
      jointParameters HingeJointParameters {
        axis 0 1 0
        anchor 0.48 -0.33 -0.3
      }
      device [
        RotationalMotor {
          name "right_wheel1"
          maxTorque 100
        }
      ]
      endPoint Solid {
        translation 0.48 -0.33 -0.3
        rotation 1 -1.5700895750559049e-16 -7.850447875279524e-17 1.5707999999999982
        children [
          USE WHEEL_SHAPE
        ]
        name "solid(1)"
        boundingObject USE WHEEL_SHAPE
        physics USE WHEEL_PH
      }
    }
    DEF LEFT_WHEEL2 HingeJoint {
      jointParameters HingeJointParameters {
        axis 0 1 0
        anchor 0 0.43 -0.3
      }
      device [
        RotationalMotor {
          name "left_wheel2"
          maxTorque 100
        }
      ]
      endPoint Solid {
        translation 0 0.43 -0.3
        rotation 1 7.850447875279514e-17 4.710268725167708e-16 1.5708000000000004
        children [
          USE WHEEL_SHAPE
        ]
        name "solid(7)"
        boundingObject USE WHEEL_SHAPE
        physics USE WHEEL_PH
      }
    }
    DEF RIGHT_WHEEL2 HingeJoint {
      jointParameters HingeJointParameters {
        axis 0 1 0
        anchor 0 -0.43 -0.3
      }
      device [
        RotationalMotor {
          name "right_wheel2"
          maxTorque 100
        }
      ]
      endPoint Solid {
        translation 0 -0.43 -0.3
        rotation 1 -4.710268725167713e-16 -3.9252239376397603e-16 1.570799999999999
        children [
          USE WHEEL_SHAPE
        ]
        name "solid(4)"
        boundingObject USE WHEEL_SHAPE
        physics USE WHEEL_PH
      }
    }
    DEF LEFT_WHEEL3 HingeJoint {
      jointParameters HingeJointParameters {
        axis 0 1 0
        anchor -0.48 0.33 -0.3
      }
      device [
        RotationalMotor {
          name "left_wheel3"
          maxTorque 100
        }
      ]
      endPoint Solid {
        translation -0.48 0.33 -0.3
        rotation 1 7.850447875279514e-17 4.710268725167708e-16 1.5708000000000004
        children [
          USE WHEEL_SHAPE
        ]
        name "solid(5)"
        boundingObject USE WHEEL_SHAPE
        physics USE WHEEL_PH
      }
    }
    DEF RIGHT_WHEEL3 HingeJoint {
      jointParameters HingeJointParameters {
        axis 0 1 0
        anchor -0.48 -0.33 -0.3
      }
      device [
        RotationalMotor {
          name "right_wheel3"
          maxTorque 100
        }
      ]
      endPoint Solid {
        translation -0.48 -0.33 -0.3
        rotation 1 -4.710268725167713e-16 -3.9252239376397603e-16 1.570799999999999
        children [
          USE WHEEL_SHAPE
        ]
        name "solid(6)"
        boundingObject USE WHEEL_SHAPE
        physics USE WHEEL_PH
      }
    }
    DEF BODY Shape {
      appearance PBRAppearance {
        baseColor 1 0 0
        roughness 1
        metalness 0
      }
      geometry Box {
        size 0.61 0.46 0.15
      }
    }
  ]
  name "ad_boxtra"
  boundingObject USE BODY
  physics Physics {
  }
  controller "six_wheeled_collision_avoidance"
}
Robot {
  translation 0.124458 1.2687 0.51
  children [
    DEF ARM_AXIS1_TRANSL SliderJoint {
      jointParameters JointParameters {
        minStop -0.2
        staticFriction 50
      }
      device [
        LinearMotor {
          name "arm_axis1_transl"
        }
      ]
      endPoint Solid {
        translation 0 0 0.2250000000000001
        children [
          DEF ARM_AXIS1_SHAPE Shape {
            appearance PBRAppearance {
              baseColor 1 0.5 0
              roughness 1
              metalness 0
            }
            geometry Box {
              size 0.05 0.05 0.3
            }
          }
          DEF ARM_AXIS2_ROT HingeJoint {
            jointParameters HingeJointParameters {
              axis 0 0 1
              anchor 0.025 0 0.12
              minStop -1.57
              maxStop 1.57
            }
            device [
              RotationalMotor {
                name "arm_axis2_rot"
              }
            ]
            endPoint Solid {
              translation 0.025 3.46945e-18 0.12
              children [
                DEF ARM_HINGE_SHAPE Shape {
                  appearance PBRAppearance {
                    baseColor 0 1 0
                    roughness 1
                    metalness 0
                  }
                  geometry Sphere {
                    radius 0.038
                  }
                }
                DEF ARM_AXIS3_TRANSL SliderJoint {
                  jointParameters JointParameters {
                    axis 1 0 0
                    minStop -0.1
                    staticFriction 50
                  }
                  device [
                    LinearMotor {
                      name "arm_axis3_transl"
                    }
                  ]
                  endPoint Solid {
                    translation 0.075 0 0
                    children [
                      DEF ARM_AXIS3_SHAPE Shape {
                        appearance PBRAppearance {
                          baseColor 1 0.5 0
                          roughness 1
                          metalness 0
                        }
                        geometry Box {
                          size 0.15 0.05 0.05
                        }
                      }
                      DEF ARM_AXIS4_ROT HingeJoint {
                        jointParameters HingeJointParameters {
                          anchor 0.075 0 0
                          minStop -1.57
                          maxStop 1.57
                        }
                        device [
                          RotationalMotor {
                            name "arm_axis4_rot"
                          }
                        ]
                        endPoint Solid {
                          translation 0.075 0 0
                          rotation 1 0 0 0
                          children [
                            USE ARM_HINGE_SHAPE
                            DEF ARM_LINK1 Solid {
                              translation 0.05 0 0
                              children [
                                DEF ARM_LINK1_SHAPE Shape {
                                  appearance PBRAppearance {
                                    baseColor 1 1 0
                                    roughness 1
                                    metalness 0
                                  }
                                  geometry Box {
                                    size 0.1 0.05 0.05
                                  }
                                }
                                DEF ARM_AXIS5_ROT HingeJoint {
                                  jointParameters HingeJointParameters {
                                    axis 0 1 0
                                    anchor 0.05 0 0
                                    minStop -1.57
                                    maxStop 1.57
                                  }
                                  device [
                                    RotationalMotor {
                                      name "arm_axis5_rot"
                                    }
                                  ]
                                  endPoint Solid {
                                    translation 0.05000000000000003 0 0
                                    rotation 0 1 0 0
                                    children [
                                      USE ARM_HINGE_SHAPE
                                      DEF ARM_LINK2 Solid {
                                        translation 0.05 0 0
                                        children [
                                          DEF ARM_LINK2_SHAPE Shape {
                                            appearance PBRAppearance {
                                              baseColor 1 1 0
                                              roughness 1
                                              metalness 0
                                            }
                                            geometry Box {
                                              size 0.1 0.05 0.05
                                            }
                                          }
                                        ]
                                        boundingObject USE ARM_LINK2_SHAPE
                                        physics Physics {
                                        }
                                      }
                                    ]
                                    boundingObject USE ARM_HINGE_SHAPE
                                    physics Physics {
                                    }
                                  }
                                }
                              ]
                              boundingObject USE ARM_LINK1_SHAPE
                              physics Physics {
                              }
                            }
                          ]
                          boundingObject USE ARM_HINGE_SHAPE
                          physics Physics {
                          }
                        }
                      }
                    ]
                    boundingObject USE ARM_AXIS3_SHAPE
                    physics Physics {
                    }
                  }
                }
              ]
              boundingObject USE ARM_HINGE_SHAPE
              physics Physics {
              }
            }
          }
        ]
        name "solid(2)"
        boundingObject USE ARM_AXIS1_SHAPE
        physics Physics {
        }
      }
    }
    DEF DS_RIGHT DistanceSensor {
      translation 0.305 -0.23 0
      rotation 0 0 1 -0.3
      children [
        DEF DS_SHAPE Shape {
          appearance PBRAppearance {
            baseColor 0 0 1
            roughness 1
            metalness 0
          }
          geometry Box {
            size 0.03 0.03 0.03
          }
        }
      ]
      name "ds_right"
      lookupTable [
        0 0 0
        0.4 1000 0
      ]
    }
    DEF DS_LEFT DistanceSensor {
      translation 0.305 0.23 0
      rotation 0 0 1 0.3
      children [
        USE DS_SHAPE
      ]
      name "ds_left"
      lookupTable [
        0 0 0
        0.4 1000 0
      ]
    }
    DEF LEFT_WHEEL1 HingeJoint {
      jointParameters HingeJointParameters {
        axis 0 1 0
        anchor 0.48 0.33 -0.3
      }
      device [
        RotationalMotor {
          name "left_wheel1"
          maxTorque 100
        }
      ]
      endPoint Solid {
        translation 0.48 0.33 -0.3
        rotation 1 -7.065403087751576e-16 -1.5700895750559056e-16 1.5707999999999966
        children [
          DEF WHEEL_SHAPE Shape {
            appearance PBRAppearance {
              baseColor 0 1 0
              roughness 1
              metalness 0
            }
            geometry Cylinder {
              height 0.1
              radius 0.1
            }
          }
        ]
        boundingObject USE WHEEL_SHAPE
        physics DEF WHEEL_PH Physics {
        }
      }
    }
    DEF RIGHT_WHEEL1 HingeJoint {
      jointParameters HingeJointParameters {
        axis 0 1 0
        anchor 0.48 -0.33 -0.3
      }
      device [
        RotationalMotor {
          name "right_wheel1"
          maxTorque 100
        }
      ]
      endPoint Solid {
        translation 0.48 -0.33 -0.3
        rotation 1 -1.5700895750559049e-16 -7.850447875279524e-17 1.5707999999999982
        children [
          USE WHEEL_SHAPE
        ]
        name "solid(1)"
        boundingObject USE WHEEL_SHAPE
        physics USE WHEEL_PH
      }
    }
    DEF LEFT_WHEEL2 HingeJoint {
      jointParameters HingeJointParameters {
        axis 0 1 0
        anchor 0 0.43 -0.3
      }
      device [
        RotationalMotor {
          name "left_wheel2"
          maxTorque 100
        }
      ]
      endPoint Solid {
        translation 0 0.43 -0.3
        rotation 1 7.850447875279514e-17 4.710268725167708e-16 1.5708000000000004
        children [
          USE WHEEL_SHAPE
        ]
        name "solid(7)"
        boundingObject USE WHEEL_SHAPE
        physics USE WHEEL_PH
      }
    }
    DEF RIGHT_WHEEL2 HingeJoint {
      jointParameters HingeJointParameters {
        axis 0 1 0
        anchor 0 -0.43 -0.3
      }
      device [
        RotationalMotor {
          name "right_wheel2"
          maxTorque 100
        }
      ]
      endPoint Solid {
        translation 0 -0.43 -0.3
        rotation 1 -4.710268725167713e-16 -3.9252239376397603e-16 1.570799999999999
        children [
          USE WHEEL_SHAPE
        ]
        name "solid(4)"
        boundingObject USE WHEEL_SHAPE
        physics USE WHEEL_PH
      }
    }
    DEF LEFT_WHEEL3 HingeJoint {
      jointParameters HingeJointParameters {
        axis 0 1 0
        anchor -0.48 0.33 -0.3
      }
      device [
        RotationalMotor {
          name "left_wheel3"
          maxTorque 100
        }
      ]
      endPoint Solid {
        translation -0.48 0.33 -0.3
        rotation 1 7.850447875279514e-17 4.710268725167708e-16 1.5708000000000004
        children [
          USE WHEEL_SHAPE
        ]
        name "solid(5)"
        boundingObject USE WHEEL_SHAPE
        physics USE WHEEL_PH
      }
    }
    DEF RIGHT_WHEEL3 HingeJoint {
      jointParameters HingeJointParameters {
        axis 0 1 0
        anchor -0.48 -0.33 -0.3
      }
      device [
        RotationalMotor {
          name "right_wheel3"
          maxTorque 100
        }
      ]
      endPoint Solid {
        translation -0.48 -0.33 -0.3
        rotation 1 -4.710268725167713e-16 -3.9252239376397603e-16 1.570799999999999
        children [
          USE WHEEL_SHAPE
        ]
        name "solid(6)"
        boundingObject USE WHEEL_SHAPE
        physics USE WHEEL_PH
      }
    }
    DEF BODY Shape {
      appearance PBRAppearance {
        baseColor 1 0 0
        roughness 1
        metalness 0
      }
      geometry Box {
        size 0.61 0.46 0.15
      }
    }
  ]
  name "ad_boxtra(1)"
  boundingObject USE BODY
  physics Physics {
  }
  controller "arm_sweep"
}
WoodenBox {
  translation -0.627376 -1.49446 0.25
  rotation 0 0 -1 -1.8326053071795858
  size 0.45 0.45 0.45
}
WoodenBox {
  translation 1.0725 0.016777 0.25
  rotation 0 0 1 1.0472
  name "wooden box(1)"
  size 0.45 0.45 0.45
}
Solid {
  translation 0.189199 -1.35491 0.25
  children [
    DEF BALL_SHAPE Shape {
      appearance PBRAppearance {
        baseColor 0.4 1 1
        roughness 0.3
        metalness 0.8
      }
      geometry Sphere {
        radius 0.2
        subdivision 2
      }
    }
  ]
  boundingObject USE BALL_SHAPE
  physics Physics {
  }
}
Solid {
  translation -0.786772 -0.289222 0.25
  children [
    DEF BALL_SHAPE Shape {
      appearance PBRAppearance {
        baseColor 1 0.6 1
        roughness 0.3
        metalness 0.8
      }
      geometry Sphere {
        radius 0.2
        subdivision 2
      }
    }
  ]
  name "solid(1)"
  boundingObject USE BALL_SHAPE
  physics Physics {
  }
}
Solid {
  translation 0.958104 -1.00132 0.25
  children [
    DEF BALL_SHAPE Shape {
      appearance PBRAppearance {
        baseColor 1 1 0.4
        roughness 0.3
        metalness 0.8
      }
      geometry Sphere {
        radius 0.2
        subdivision 2
      }
    }
  ]
  name "solid(2)"
  boundingObject USE BALL_SHAPE
  physics Physics {
  }
}
